<?xml version="1.0"?>
<robot xmlns:xacro="http://www.ros.org/wiki/xacro">

    <link name="base_link"/>
    <!-- Chassis joint  -->
    <joint name="chassis_joint" type="fixed">
        <parent link="base_link"/>
        <child link="chassis"/>
        <origin xyz="0.0 0.0 0.0"/>
    </joint>

    <!-- Chassis Link -->
    <link name="chassis">
        <visual>
            <origin 
            xyz="0.0 0.0 0.0"
            rpy="0.0 0.0 0.0"/>
            <geometry>
                <mesh 
                  filename="package://minimal_driver/meshes/base_link.STL" />
            </geometry>
        </visual>
        <collision>
            <origin
              xyz="0.0 0.0 0.0"
              rpy="0.0 0.0 0.0" />
            <geometry>
              <mesh
                filename="package://minimal_driver/meshes/base_link.STL" />
            </geometry>
        </collision>
    </link>

    <!-- Left Wheel Link -->
     <joint name="left_wheel_joint" type="continuous">
        <parent link="base_link"/>
        <child link="left_wheel_link"/>
        <origin
            xyz="0.0 0.08 0.0"
            rpy="-${pi/2} 0 0" />
        <axis xyz="0.0 0.0 1.0"/>
     </joint>

     <link name="left_wheel_link">
        <visual>
        <origin
            xyz="0 0 0"
            rpy="0 0 0" />
        <geometry>
            <mesh
            filename="package://minimal_driver/meshes/left_wheel_link.STL" />
        </geometry>
        </visual>
        <collision>
            <origin
              xyz="0 0 0"
              rpy="0 0 0" />
            <geometry>
              <mesh
                filename="package://minimal_driver/meshes/left_wheel_link.STL" />
            </geometry>
        </collision>
     </link>


     <!-- Right Wheel Link -->
     <joint name="right_wheel_joint" type="continuous">
        <parent link="base_link"/>
        <child link="right_wheel_link"/>
        <origin
            xyz="0.0 -0.08 0.0"
            rpy="${pi/2} 0 0" />
        <axis xyz="0.0 0.0 -1.0"/>
     </joint>

     <link name="right_wheel_link">
        <visual>
        <origin
            xyz="0 0 0"
            rpy="0 0 0" />
        <geometry>
            <mesh
            filename="package://minimal_driver/meshes/right_wheel_link.STL" />
        </geometry>
        </visual>
        <collision>
            <origin
              xyz="0 0 0"
              rpy="0 0 0" />
            <geometry>
              <mesh
                filename="package://minimal_driver/meshes/right_wheel_link.STL" />
            </geometry>
        </collision>
     </link>
</robot>